{"uid":"4b4757e66a1912dae1a509f688f20b0f","name":"categories","children":[{"name":"Test defects","children":[{"name":"`cy.should()` failed because you invoked a command inside the callback. `cy.should()` retries the inner function, which would result in commands being added to the queue multiple times. Use `cy.then()` instead of `cy.should()`, or move any commands outside the callback function.\n                \n                The command invoked was:\n                \n                  > `cy.task()`","children":[{"name":"should assert against a function for inventory items","uid":"175028f7d02f804a","parentUid":"cfa2261285de5b7f115fdf31c03266d4","status":"broken","time":{"start":1758169799526,"stop":1758169801202,"duration":1676},"flaky":false,"newFailed":false,"newPassed":false,"newBroken":false,"retriesCount":0,"retriesStatusChange":false,"parameters":[],"tags":[]}],"uid":"cfa2261285de5b7f115fdf31c03266d4"}],"uid":"bdbf199525818fae7a8651db9eafe741"}]}